Workbook

Sheet Start Here
A1: Getting Found in Oakville — six-month tracker
A2: Working file for Luxury Beauty by Cleo R. Companion to seo-roadmap-6-month.docx
A5: THE SHAPE OF IT
A6: Runs | B6: Monday 17 August 2026 to Sunday 14 February 2027. Twenty-six weeks, six months.
A7: Right now | B7: The rest of August is Google Business Profile and citations. Nothing else.
A8: Week of Aug 24 | B8: Website planning and design. Sitemap, wireframes, keyword-to-page map, copy outline.
A9: Aug 31 | B9: Design sign-off. This is the date the build waits on.
A10: Sept 1 | B10: Build starts. Launch target is the week of 5 October.
A12: HOW THIS WORKS
A13: Every day | B13: Open the Daily Log. Six slots, five of them daily, the reel on Wednesday. Mark each one.
A14: The routine | B14: The Daily Routine tab says what each slot actually means. Read it once, then work off the log.
A15: The projects | B15: The Tasks tab holds the one-off work. Filter Status to 'In progress' and 'Not started'.
A16: You edit | B16: Status, Date done, and Notes. Leave the rest unless the plan genuinely changes.
A17: Blocked? | B17: Set Status to Blocked and write what you are waiting on in Notes. Blocked rows turn red.
A18: Weekly | B18: Monday: profile insights. Wednesday: batch the content and film the reel. Friday: log the week.
A19: Monthly | B19: Fill the Metrics tab. Compare against the baseline column, not against last month.
A21: THE TWO THINGS THAT DECIDE THIS
A22: Reviews | B22: Twelve today. The ask goes out inside 24 hours of every appointment or the number does not move.
A23: The daily log | B23: Five slots a day is not a lot. Missing them for a fortnight undoes a month of the rest.
A25: WHERE THINGS STAND
A26: Project tasks | B26: =COUNTA(Tasks!F2:F149)
A27: Not started | B27: =COUNTIF(Tasks!J2:J149,"Not started")
A28: In progress | B28: =COUNTIF(Tasks!J2:J149,"In progress")
A29: Blocked | B29: =COUNTIF(Tasks!J2:J149,"Blocked")
A30: Done | B30: =COUNTIF(Tasks!J2:J149,"Done")
A31: Overdue and not done | B31: =SUMPRODUCT((Tasks!D2:D149<TODAY())*(Tasks!J2:J149<>"Done")*(Tasks!J2:J149<>"Not applicable"))
A32: Percent complete | B32: =IFERROR(COUNTIF(Tasks!J2:J149,"Done")/COUNTA(Tasks!F2:F149),0)
A33: Daily slots done | B33: ='Daily Log'!G2
A34: Daily slots missed | B34: ='Daily Log'!I2
A35: Daily completion rate | B35: ='Daily Log'!K2
A37: Import to Google Sheets: drive.google.com > New > File upload > pick this file > open with Google Sheets.

Sheet Daily Routine
A1: The daily routine
A2: Six slots. Five of them every weekday, the reel on Wednesday. This is the tab that explains the work; the Daily Log is the tab you tick.
A4: Slot | B4: Task | C4: Cadence | D4: What it involves | E4: Owner | F4: Logged on | G4: Status
A5: EVERY DAY
A6: 1 | B6: Google Business Profile post | C6: Every weekday | D6: One post a day. Rotate the five types across the week: treatment spotlight, FAQ or myth, before and after, offer or availability, practice update. Copy and images come from the content calendar. Every post ends with the booking link. | E6: Cleo | F6: GBP Posts tab | G6: Not started
A7: 2 | B7: Instagram post or stories | C7: Every weekday | D7: A feed post on the calendar days, two or three stories on the rest. Location-tag Oakville every time, write the alt text every time, use the local hashtag set. | E7: Cleo | F7: Content calendar | G7: Not started
A8: 3 | B8: Reel | C8: Once a week — Wednesday | D8: One reel a week, filmed and cut in the Wednesday batch block. Rotate the four types across the month: a treatment in fifteen seconds, a myth-buster, behind the scenes in the room, a patient question answered to camera. Reuse each cut as a story and a GBP video. | E8: Cleo | F8: Daily Log tab | G8: Not started
A9: 4 | B9: On-page optimisation | C9: Every weekday | D9: Before launch: keyword-to-page mapping, drafting title tags and meta descriptions, writing page copy for the build. After launch: one page improved a day on rotation — title tag, H1, internal links, image alt text, schema, thin content topped up. | E9: Agency | F9: Tasks tab | G9: Not started
A10: 5 | B10: Review ask | C10: Every weekday | D10: The WhatsApp message inside 24 hours to every patient seen that day, and a reply to any review that landed. This is the single highest-return thing in the plan. | E10: Cleo | F10: Reviews tab | G10: Not started
A11: 6 | B11: Citations | C11: Daily to week 4, then weekly | D11: One directory a day claimed or corrected until the list is clean, then one a week to keep it clean. Name, address and phone identical everywhere, no exceptions. | E11: Agency | F11: Citations tab | G11: Not started
A12: EVERY WEEK
A13: Mon | B13: Google profile insights and rank check | C13: Weekly | D13: Calls, views and direction requests for the week. Where the map pack has you for the three target terms. Two minutes, written down, every Monday. | E13: Agency | F13: Metrics tab | G13: Not started
A14: Wed | B14: Content and reel batch | C14: Weekly | D14: Film the reel, batch the week's GBP posts and Instagram captions so the daily slots are a five-minute publish rather than a blank page. | E14: Both | F14: Content calendar | G14: Not started
A15: Fri | B15: Log the week | C15: Weekly | D15: Fill in the week's numbers, close out the Tasks tab, flag anything blocked. Ad review every second Friday. | E15: Agency | F15: Tasks tab | G15: Not started
A16: EVERY MONTH
B17: Fill the Metrics tab | C17: Monthly | D17: Every number for the month end. Compare against the baseline column, not against last month. | E17: Agency | F17: Metrics tab | G17: Not started
B18: Refresh the Google profile | C18: Monthly | D18: Services list, questions and answers, photo set. A profile that never changes stops earning. | E18: Agency | F18: Tasks tab | G18: Not started
B19: Competitor and query check | C19: Monthly | D19: What the three named competitors are doing, and which queries Search Console shows you sitting just outside the first page for. | E19: Agency | F19: Metrics tab | G19: Not started
B20: Review the month's best work | C20: Monthly | D20: The posts that drove profile visits and the pages that drove sessions. More of those next month. | E20: Both | F20: Metrics tab | G20: Not started
B22: The reel is once a week, on Wednesday, filmed in the Wednesday batch block. Do not try to do one a day.
B23: Before the site is live, the on-page slot is preparation: keyword mapping, title tags, meta descriptions, page copy.
B24: From launch onward it is one real page improved a day, on rotation, so no page goes six months untouched.
B25: Compliance applies to Google posts exactly as it applies to Instagram. Nothing names a prescription drug.

Sheet Daily Log
A1: Daily log
A2: One row per weekday, 17 August 2026 to 12 February 2027. Mark each slot Done, Missed or N/A. The reel column is only live on Wednesdays. | F2: Slots done | G2: =COUNTIF(D6:I141,"Done") | H2: Slots missed | I2: =COUNTIF(D6:I141,"Missed") | J2: Completion | K2: =IFERROR(COUNTIF(D6:I141,"Done")/(COUNTIF(D6:I141,"Done")+COUNTIF(D6:I141,"Missed")),0)
D3: GBP posts | E3: =COUNTIF(D6:D141,"Done") | F3: Reels | G3: =COUNTIF(F6:F141,"Done") | H3: Review asks | I3: =COUNTIF(H6:H141,"Done") | J3: Days logged | K3: =COUNTIF(J6:J141,">0")
A4: Date | B4: Day | C4: Week | D4: GBP post | E4: IG post / story | F4: Reel | G4: On-page | H4: Review ask | I4: Citation | J4: Done | K4: Notes
A5: AUGUST 2026
A6: 46251 | B6: Mon | C6: W1 | F6: N/A | J6: =COUNTIF(D6:I6,"Done")
A7: 46252 | B7: Tue | C7: W1 | F7: N/A | J7: =COUNTIF(D7:I7,"Done")
A8: 46253 | B8: Wed | C8: W1 | J8: =COUNTIF(D8:I8,"Done")
A9: 46254 | B9: Thu | C9: W1 | F9: N/A | J9: =COUNTIF(D9:I9,"Done")
A10: 46255 | B10: Fri | C10: W1 | F10: N/A | J10: =COUNTIF(D10:I10,"Done")
A11: 46258 | B11: Mon | C11: W2 | F11: N/A | J11: =COUNTIF(D11:I11,"Done")
A12: 46259 | B12: Tue | C12: W2 | F12: N/A | J12: =COUNTIF(D12:I12,"Done")
A13: 46260 | B13: Wed | C13: W2 | J13: =COUNTIF(D13:I13,"Done")
A14: 46261 | B14: Thu | C14: W2 | F14: N/A | J14: =COUNTIF(D14:I14,"Done")
A15: 46262 | B15: Fri | C15: W2 | F15: N/A | J15: =COUNTIF(D15:I15,"Done")
A16: 46265 | B16: Mon | C16: W3 | F16: N/A | J16: =COUNTIF(D16:I16,"Done")
A17: SEPTEMBER 2026
A18: 46266 | B18: Tue | C18: W3 | F18: N/A | J18: =COUNTIF(D18:I18,"Done")
A19: 46267 | B19: Wed | C19: W3 | J19: =COUNTIF(D19:I19,"Done")
A20: 46268 | B20: Thu | C20: W3 | F20: N/A | J20: =COUNTIF(D20:I20,"Done")
A21: 46269 | B21: Fri | C21: W3 | F21: N/A | J21: =COUNTIF(D21:I21,"Done")
A22: 46272 | B22: Mon | C22: W4 | F22: N/A | J22: =COUNTIF(D22:I22,"Done")
A23: 46273 | B23: Tue | C23: W4 | F23: N/A | J23: =COUNTIF(D23:I23,"Done")
A24: 46274 | B24: Wed | C24: W4 | J24: =COUNTIF(D24:I24,"Done")
A25: 46275 | B25: Thu | C25: W4 | F25: N/A | J25: =COUNTIF(D25:I25,"Done")
A26: 46276 | B26: Fri | C26: W4 | F26: N/A | J26: =COUNTIF(D26:I26,"Done")
A27: 46279 | B27: Mon | C27: W5 | F27: N/A | J27: =COUNTIF(D27:I27,"Done")
A28: 46280 | B28: Tue | C28: W5 | F28: N/A | J28: =COUNTIF(D28:I28,"Done")
A29: 46281 | B29: Wed | C29: W5 | J29: =COUNTIF(D29:I29,"Done")
A30: 46282 | B30: Thu | C30: W5 | F30: N/A | J30: =COUNTIF(D30:I30,"Done")
A31: 46283 | B31: Fri | C31: W5 | F31: N/A | J31: =COUNTIF(D31:I31,"Done")
A32: 46286 | B32: Mon | C32: W6 | F32: N/A | J32: =COUNTIF(D32:I32,"Done")
A33: 46287 | B33: Tue | C33: W6 | F33: N/A | J33: =COUNTIF(D33:I33,"Done")
A34: 46288 | B34: Wed | C34: W6 | J34: =COUNTIF(D34:I34,"Done")
A35: 46289 | B35: Thu | C35: W6 | F35: N/A | J35: =COUNTIF(D35:I35,"Done")
A36: 46290 | B36: Fri | C36: W6 | F36: N/A | J36: =COUNTIF(D36:I36,"Done")
A37: 46293 | B37: Mon | C37: W7 | F37: N/A | J37: =COUNTIF(D37:I37,"Done")
A38: 46294 | B38: Tue | C38: W7 | F38: N/A | J38: =COUNTIF(D38:I38,"Done")
A39: 46295 | B39: Wed | C39: W7 | J39: =COUNTIF(D39:I39,"Done")
A40: OCTOBER 2026
...

Sheet Tasks
A1: ID | B1: Month | C1: Week | D1: Due | E1: Area | F1: Task | G1: Owner | H1: Cadence | I1: Priority | J1: Status | K1: Date done | L1: Notes / blockers
A2: 1 | B2: Month 1 | C2: W1 | D2: 46257 | E2: Google profile | F2: Find out who owns the Google Business Profile and which email holds it | G2: Cleo | H2: One-off | I2: High | J2: Not started
A3: 2 | B3: Month 1 | C3: W1 | D3: 46257 | E3: Google profile | F3: Confirm with Allure whether you can use your own signage and suite designation | G3: Cleo | H3: One-off | I3: High | J3: Not started
A4: 3 | B4: Month 1 | C4: W1 | D4: 46257 | E4: Google profile | F4: Claim and verify the Google Business Profile | G4: Agency | H4: One-off | I4: High | J4: Not started
A5: 4 | B5: Month 1 | C5: W1 | D5: 46257 | E5: Google profile | F5: Correct the GBP address to L6M 0T9 and add the suite designation | G5: Agency | H5: One-off | I5: High | J5: Not started
A6: 5 | B6: Month 1 | C6: W1 | D6: 46257 | E6: Google profile | F6: Set real opening hours on GBP for every day of the week | G6: Agency | H6: One-off | I6: High | J6: Not started
A7: 6 | B7: Month 1 | C7: W1 | D7: 46257 | E7: Google profile | F7: Choose the primary GBP category | G7: Agency | H7: One-off | I7: High | J7: Not started
A8: 7 | B8: Month 1 | C8: W1 | D8: 46257 | E8: Google profile | F8: Choose secondary categories that avoid colliding with Allure's listing | G8: Agency | H8: One-off | I8: High | J8: Not started
A9: 8 | B9: Month 1 | C9: W1 | D9: 46257 | E9: Google profile | F9: Replace the dead website link on GBP with the booking link until the site is live | G9: Agency | H9: One-off | I9: High | J9: Not started
A10: 9 | B10: Month 1 | C10: W1 | D10: 46257 | E10: Google profile | F10: Upload real photos to GBP: treatment room, you, the space | G10: Both | H10: One-off | I10: High | J10: Not started
A11: 10 | B11: Month 1 | C11: W1 | D11: 46257 | E11: Citations | F11: Decide on one email address and one phone number to use everywhere | G11: Cleo | H11: One-off | I11: High | J11: Not started
A12: 11 | B12: Month 1 | C12: W1 | D12: 46257 | E12: Citations | F12: Audit every listing that mentions the practice and record the wrong NAP on the Citations tab | G12: Agency | H12: One-off | I12: High | J12: Not started
A13: 12 | B13: Month 1 | C13: W1 | D13: 46257 | E13: Daily routine | F13: Start the daily routine: GBP post, Instagram, on-page, review ask, citation | G13: Cleo | H13: Daily | I13: High | J13: Not started
... A149: 148 | B149: Month 6 | C149: W26 | D149: 46432 | E149: Website | F149: Hand over the site documentation and every login | G149: Agency | H149: One-off | I149: High | J149: Not started

Sheet Site Build
A1: Website build timeline
A2: Approved, full build. Real dates, not weeks-from-approval. Everything after 31 August slips one-for-one if the design sign-off slips.
A4: When | B4: What we do | C4: What we need from Cleo | D4: Status | E4: Date done | F4: Notes
A5: Aug 24 - 28 | B5: Planning and design: sitemap, page inventory, wireframes for home, contact and the treatment template, keyword-to-page map, brand kit pulled from design/brand | C5: Registrar login, treatment list with current pricing, photos of the room, a headshot, logo files | D5: Not started
A6: Aug 31 | B6: Design sign-off. This is the gate — nothing is built before it clears | C6: Sign off the wireframes and the look, in writing | D6: Not started
A7: Sep 1 - 6 | B7: BUILD STARTS. Hosting sorted, DNS pointed at the new site, platform set up, page structure scaffolded | C7: Nothing. This week is ours | D7: Not started
A8: Sep 7 - 13 | B8: Home and contact complete in staging: corrected address at L6M 0T9, real hours, booking link, LocalBusiness and Service schema, title tags and meta descriptions | C8: Read the home page copy and approve it | D8: Not started
A9: Sep 14 - 27 | B9: Treatment pages: lip filler, dermal filler and facial balancing, anti-wrinkle injections, skin boosters. Internal linking, image compression, alt text | C9: Read the copy and confirm every claim is one you can stand behind | D9: Not started
A10: Sep 28 - Oct 4 | B10: Remaining treatment pages: dermaplaning, electrolysis, Belkyra. The Oakville and surrounding-area page. Mobile speed pass | C10: Nothing. This week is ours | D10: Not started
A11: Oct 5 - 11 | B11: LAUNCH. Search Console verified, sitemap submitted, analytics running, GBP website field repointed, every citation updated to the new URL | C11: Final sign-off before it goes live | D11: Not started
A12: Oct 12 - Nov 8 | B12: Indexing and on-page. Fix whatever Search Console flags, FAQ schema on the treatment pages, the first three question-intent articles | C12: The questions you get asked most in consults | D12: Not started
A13: Nov 9 - Feb 14 | B13: Depth. Weight-loss page, before-and-after gallery, five more articles, near-miss query optimisation, technical audit, handover | C13: Consent-cleared photos as they come, and the consult questions | D13: Not started

Sheet Reviews
A1: Review tracker
A2: Baseline 12 reviews at 5.0. Target 18 to 22 new ones across the six months, roughly one every ten days. Ask inside 24 hours or the number does not move. | F2: Asks sent | G2: =COUNTA(A5:A164) | H2: Reviews landed | I2: =COUNTIF(E5:E164,"Yes")
A4: Date asked | B4: Patient (initials) | C4: How we asked | D4: Asked by | E4: Review received | F4: Date received | G4: Platform | H4: Replied | I4: Notes

Sheet Citations
A1: Citations and NAP
A2: One name, one address, one phone number, everywhere. The postal code is L6M 0T9 — it is wrong on most of these today.
A4: Directory | B4: Listing URL | C4: Claimed | D4: Name correct | E4: Address and postal code correct | F4: Phone correct | G4: Website URL current | H4: Status | I4: Date done | J4: Notes
A5: Google Business Profile | H5: Not started
A6: Birdeye | H6: Not started
A7: Facebook | H7: Not started
A8: Fresha | H8: Not started
A9: Yelp.ca | H9: Not started
A10: Yellow Pages | H10: Not started
A11: Apple Maps | H11: Not started
A12: Bing Places | H12: Not started
A13: RateMDs | H13: Not started
A14: Canadian chamber directories | H14: Not started
A15: Oakville Chamber of Commerce | H15: Not started
A16: 411.ca | H16: Not started
... A21: Halton business directory | H21: Not started

Sheet GBP Posts
A1: Google Business Profile posts
A2: One a day, every weekday. Rotate the five types. Every post carries the booking link. Nothing here names a prescription drug. | F2: Posts published | G2: =COUNTIF(G5:G144,"Yes")
A4: Date | B4: Post type | C4: Treatment or topic | D4: Copy source | E4: Image source | F4: Booking link included | G4: Published | H4: Notes

Sheet Metrics
A1: Monthly numbers
A2: Fill at the end of each month. Compare against the baseline column, not against last month.
A4: What we track | B4: Baseline (17 Aug) | C4: Target by 14 Feb | D4: End Sep | E4: End Oct | F4: End Nov | G4: End Dec | H4: End Jan | I4: Mid Feb | J4: Notes
A5: Google reviews | B5: 12 | C5: 30 to 34, still at or near 5.0
A6: Google review average | B6: 5.0 | C6: At or near 5.0
A7: Calls from Google profile | C7: Up on baseline every month
A8: Direction requests from Google | C8: Up on baseline every month
A9: Google profile views | C9: Up on baseline every month
A10: GBP posts published in the month | B10: 0 | C10: 20 or more, every month
A11: Map pack position: nurse injector oakville | C11: Visible in the pack
A12: Map pack position: botox oakville | C12: Visible in the pack
A13: Map pack position: lip filler oakville | C13: Visible in the pack
A14: Instagram profile visits | C14: Up on baseline
A15: Instagram link taps | C15: Rising faster than profile visits
A16: Reels published in the month | B16: 0 | C16: Four, one a week
A17: DMs received | B17: Not tracked | C17: Tracked weekly from week 1
A18: Consultations booked | B18: Not tracked | C18: Tracked weekly, attributed to source
A19: Ad spend | B19: Not supplied | C19: Confirmed and split 70/20/10
A20: Cost per DM from ads | C20: Falling month on month
A21: Website sessions | B21: No site | C21: From launch in October, rising month on month
A22: Search Console impressions | B22: No site | C22: Rising month on month from October
A23: Pages indexed | B23: No site | C23: Every page, confirmed in Search Console
A24: Daily slot completion rate | C24: 85 per cent or better

Sheet Waiting On Cleo
A1: Waiting on Cleo
A2: Access, assets and answers. Most delay in work like this comes from waiting on these. The top four are what the build waits on.
A4: Type | B4: What we need | C4: Needed by | D4: Why it blocks us | E4: Status | F4: Date received | G4: Notes
A5: Access | B5: Google Business Profile, and which email holds it | C5: 46255 | D5: Nothing on the profile can start until this is settled | E5: Not started
A6: Answer | B6: Real opening hours for every day | C6: 46255 | D6: The hours on Google are wrong until we have these | E6: Not started
A7: Asset | B7: Treatment list with current pricing | C7: 46260 | D7: Sitemap, service pages and the GBP services list all key off it | E7: Not started
A8: Access | B8: Domain registrar login for luxurybeautybycleo.ca | C8: 46262 | D8: DNS has to be pointed before the build can start on 1 September | E8: Not started
A9: Answer | B9: DESIGN SIGN-OFF on the wireframes and the look | C9: 46265 | D9: The build gate. Everything after it slips one-for-one | E9: Not started
A10: Asset | B10: Photos of the treatment room and the space | C10: 46262 | D10: GBP photos and every website page | E10: Not started
A11: Asset | B11: A current headshot | C11: 46262 | D11: GBP, Instagram and the site | E11: Not started
A12: Asset | B12: Logo files and any brand assets you already have | C12: 46262 | D12: The design cannot be finalised without them | E12: Not started
A13: Asset | B13: Signed before-and-after consent form | C13: 46271 | D13: Determines what we are allowed to publish anywhere | E13: Not started
A14: Access | B14: Meta Business account and ad account | C14: 46285 | D14: Needed to build audiences and run ads | E14: Not started
A15: Access | B15: Instagram collaborator invitation | C15: 46262 | D15: Needed to fix the name field, bio and link | E15: Not started
A16: Access | B16: Booking system login | C16: 46271 | D16: Needed for the booking link and the lookalike audience | E16: Not started
... A24: Answer | B24: Commitment to the daily routine | C24: 46255 | D24: Five slots a day. Without them the rest of the plan does not compound | E24: Not started
