Workbook

Sheet Start Here
A1: Getting Found in Oakville — six-month tracker
A2: Working file for Luxury Beauty by Cleo R. Companion to seo-roadmap-6-month.docx
A5: THE SHAPE OF IT
A6: Runs | B6: Monday 17 August 2026 to Sunday 14 February 2027. Twenty-six weeks, six months.
A7: Right now | B7: The rest of August is Google Business Profile and citations. Nothing else.
A8: Week of Aug 24 | B8: Website planning and design. Sitemap, wireframes, keyword-to-page map, copy outline.
A9: Aug 31 | B9: Design sign-off. This is the date the build waits on.
A10: Sept 1 | B10: Build starts. Launch target is the week of 5 October.
A13: Field | B13: Value | E13: Where it gets decided
A14: Business name (exact) | B14: Luxury Beauty by Cleo R. | E14: Use this spelling everywhere. No 'Med Spa', no 'Inc', no variations
A15: Practitioner | B15: Cleo Rukovo, NP | E15: Nurse practitioner. Some healthcare directories list the person, not the practice
A16: Address line 1 | B16: 3060 Preserve Drive | E16: Confirmed
A17: Suite / unit | E17: Waiting on the Allure conversation. This is what separates you from their listing
A18: City | B18: Oakville | E18: Confirmed
A19: Province | B19: Ontario | E19: Write 'Ontario' in full, or 'ON' — pick one and never mix them
A20: Postal code | B20: L6M 4L9 | E20: Confirmed by Cleo, 21 Aug 2026. Listings showing L6M 0T9 are the error - verify against Canada Post before the mass correction
A21: Country | B21: Canada | E21: Confirmed
A22: Phone | B22: (416) 294-0452 | E22: One number, everywhere. A local 905 or 289 line beats the 416 mobile if you can get one
A23: Email | B23: Luxury.beautyaestheticz@gmail.com | E23: One address. Currently split between crukovo@ and luxury.beautyaestheticz@
A24: Website | B24: https://luxurybeautybycleo.ca | E24: Use the booking link until the site is live in October, then switch every listing
A25: Booking URL | B25: IG only | E25: Needed before any directory that offers a booking button
A26: Primary category | B26: Medical Spa | E26: Set on the Google profile first, then match it everywhere else
A27: Secondary categories | B27: Skin care clinic Weight loss service | E27: Chosen to avoid colliding with Allure's listing
A28: Short description (under 250 characters) | E28: Names the town and the treatments. No prescription drug names, no benefit claims
A29: Long description | B29: Luxury Beauty by Cleo R. is a nurse practitioner-led medical spa in Oakville, Ontario, serving clients across Burlington, Mississauga, Milton and Halton Region. Our services include lip filler, dermal filler for volume loss, anti-wrinkle injections, jawline slimming, skin boosters for hydration and glow, dermaplaning, and electrolysis. Every visit begins with a one-on-one consultation so we can plan the right approach for your features and your goals. Our philosophy is simple: the right product, the right technique, and never more than you need. Every treatment is performed by Cleo Rukovo, NP. Book your consultation today. | E29: Same rules. Write once, reuse everywhere
A30: Hours — Monday | B30: Closed | E30: All seven days. 'Closed' is an answer; blank is not
A31: Hours — Tuesday | B31: Closed
A32: Hours — Wednesday | B32: Closed
A33: Hours — Thursday | B33: Closed
A34: Hours — Friday | B34: 10:00 AM–8:00 PM
A35: Hours — Saturday | B35: Closed
A36: Hours — Sunday | B36: Closed | E36: The only hours on record anywhere today are Sunday 12 to 5
A37: Year established | B37: 2023
A38: Service area | B38: Oakville, Burlington, Milton, Mississauga, Glen Abbey, Joshua Creek, Bronte | E38: Used where a directory asks for a service radius
A39: Logo file | B39: added | E39: From design/brand
A40: Cover photo | B40: added
A45: WHERE THINGS STAND
A46: Project tasks | B46: =COUNTA(Tasks!F2:F160)
A47: Not started | B47: =COUNTIF(Tasks!J2:J160,"Not started")
A48: In progress | B48: =COUNTIF(Tasks!J2:J160,"In progress")
...

Sheet Daily Routine
A1: The daily routine
A2: Six slots. Five of them every weekday, the reel on Wednesday. This is the tab that explains the work; the Daily Log is the tab you tick.
A4: Slot | B4: Task | C4: Cadence | D4: What it involves | E4: Owner | F4: Logged on | G4: Status
A5: EVERY DAY
A6: 1 | B6: Google Business Profile post | C6: Every weekday | D6: One post a day. Rotate the five types across the week: treatment spotlight, FAQ or myth, before and after, offer or availability, practice update. Copy and images come from the content calendar. Every post ends with the booking link. | E6: Cleo | F6: GBP Posts tab | G6: In progress
A7: 2 | B7: Instagram post or stories | C7: Every weekday | D7: A feed post on the calendar days, two or three stories on the rest. Location-tag Oakville every time, write the alt text every time, use the local hashtag set. | E7: Cleo | F7: Content calendar | G7: In progress
A8: 3 | B8: Reel | C8: Once a week — Wednesday | D8: One reel a week, filmed and cut in the Wednesday batch block. Rotate the four types across the month: a treatment in fifteen seconds, a myth-buster, behind the scenes in the room, a patient question answered to camera. Reuse each cut as a story and a GBP video. | E8: Cleo | F8: Daily Log tab | G8: In progress
A9: 4 | B9: On-page optimisation | C9: Every weekday | D9: Before launch: keyword-to-page mapping, drafting title tags and meta descriptions, writing page copy for the build. After launch: one page improved a day on rotation — title tag, H1, internal links, image alt text, schema, thin content topped up. | E9: Agency | F9: Tasks tab | G9: Not started
A10: 5 | B10: Review ask | C10: Every weekday | D10: The WhatsApp message inside 24 hours to every patient seen that day, and a reply to any review that landed. This is the single highest-return thing in the plan. | E10: Cleo | F10: Reviews tab | G10: Not applicable
A11: 6 | B11: Citations | C11: Daily to week 4, then weekly | D11: One directory a day. The Citations tab first ,the listings that exist and are wrong , then the Local Citations build list, where there is no listing at all. Once both are clean, one a week to keep them that way. Name, address and phone identical everywhere, no exceptions. | E11: Agency | F11: Citations + Local Citations | G11: Not started
A12: EVERY WEEK
A13: Mon | B13: Google profile insights and rank check | C13: Weekly | D13: Calls, views and direction requests for the week. Where the map pack has you for the three target terms. Two minutes, written down, every Monday. | E13: Agency | F13: Metrics tab | G13: In progress
A14: Wed | B14: Content and reel batch | C14: Weekly | D14: Film the reel, batch the week's GBP posts and Instagram captions so the daily slots are a five-minute publish rather than a blank page. | E14: Both | F14: Content calendar | G14: Not started
A15: Fri | B15: Log the week | C15: Weekly | D15: Fill in the week's numbers, close out the Tasks tab, flag anything blocked. Ad review every second Friday. | E15: Agency | F15: Tasks tab | G15: Not started
A16: EVERY MONTH
B17: Fill the Metrics tab | C17: Monthly | D17: Every number for the month end. Compare against the baseline column, not against last month. | E17: Agency | F17: Metrics tab | G17: Not started
B18: Refresh the Google profile | C18: Monthly | D18: Services list, questions and answers, photo set. A profile that never changes stops earning. | E18: Agency | F18: Tasks tab | G18: Not started
B19: Competitor and query check | C19: Monthly | D19: What the three named competitors are doing, and which queries Search Console shows you sitting just outside the first page for. | E19: Agency | F19: Metrics tab | G19: Not started
B20: Review the month's best work | C20: Monthly | D20: The posts that drove profile visits and the pages that drove sessions. More of those next month. | E20: Both | F20: Metrics tab | G20: Not started
B22: The reel is once a week, on Wednesday, filmed in the Wednesday batch block. Do not try to do one a day.
B23: Before the site is live, the on-page slot is preparation: keyword mapping, title tags, meta descriptions, page copy.
B24: From launch onward it is one real page improved a day, on rotation, so no page goes six months untouched.
B25: Compliance applies to Google posts exactly as it applies to Instagram. Nothing names a prescription drug.

Sheet Daily Log
A1: Daily log
A2: One row per weekday, 17 August 2026 to 12 February 2027. Mark each slot Done, Missed or N/A. The reel column is only live on Wednesdays. | F2: Slots done | G2: =COUNTIF(D6:I141,"Done") | H2: Slots missed | I2: =COUNTIF(D6:I141,"Missed") | J2: Completion | K2: =IFERROR(COUNTIF(D6:I141,"Done")/(COUNTIF(D6:I141,"Done")+COUNTIF(D6:I141,"Missed")),0)
D3: GBP posts | E3: =COUNTIF(D6:D141,"Done") | F3: Reels | G3: =COUNTIF(F6:F141,"Done") | H3: Review asks | I3: =COUNTIF(H6:H141,"Done") | J3: Days logged | K3: =COUNTIF(J6:J141,">0")
A4: Date | B4: Day | C4: Week | D4: GBP post | E4: IG post / story | F4: Reel | G4: On-page | H4: Review ask | I4: Citation | J4: Done | K4: Notes
A5: AUGUST 2026
A6: 46251 | B6: Mon | C6: W1 | D6: Done | E6: Done | F6: Done | G6: N/A | H6: N/A | J6: =COUNTIF(D6:I6,"Done")
A7: 46252 | B7: Tue | C7: W1 | D7: Done | E7: Done | F7: Done | G7: N/A | H7: N/A | J7: =COUNTIF(D7:I7,"Done")
A8: 46253 | B8: Wed | C8: W1 | D8: Done | E8: Done | F8: Done | G8: N/A | H8: N/A | J8: =COUNTIF(D8:I8,"Done")
A9: 46254 | B9: Thu | C9: W1 | D9: Done | E9: Done | F9: N/A | G9: N/A | H9: N/A | J9: =COUNTIF(D9:I9,"Done")
A10: 46255 | B10: Fri | C10: W1 | F10: N/A | J10: =COUNTIF(D10:I10,"Done")
A11: 46258 | B11: Mon | C11: W2 | F11: N/A | J11: =COUNTIF(D11:I11,"Done")
A12: 46259 | B12: Tue | C12: W2 | F12: N/A | J12: =COUNTIF(D12:I12,"Done")
A13: 46260 | B13: Wed | C13: W2 | J13: =COUNTIF(D13:I13,"Done")
A14: 46261 | B14: Thu | C14: W2 | F14: N/A | J14: =COUNTIF(D14:I14,"Done")
A15: 46262 | B15: Fri | C15: W2 | F15: N/A | J15: =COUNTIF(D15:I15,"Done")
A16: 46265 | B16: Mon | C16: W3 | F16: N/A | J16: =COUNTIF(D16:I16,"Done")
A17: SEPTEMBER 2026
A18: 46266 | B18: Tue | C18: W3 | F18: N/A | J18: =COUNTIF(D18:I18,"Done")
A19: 46267 | B19: Wed | C19: W3 | J19: =COUNTIF(D19:I19,"Done")
A20: 46268 | B20: Thu | C20: W3 | F20: N/A | J20: =COUNTIF(D20:I20,"Done")
A21: 46269 | B21: Fri | C21: W3 | F21: N/A | J21: =COUNTIF(D21:I21,"Done")
A22: 46272 | B22: Mon | C22: W4 | F22: N/A | J22: =COUNTIF(D22:I22,"Done")
A23: 46273 | B23: Tue | C23: W4 | F23: N/A | J23: =COUNTIF(D23:I23,"Done")
A24: 46274 | B24: Wed | C24: W4 | J24: =COUNTIF(D24:I24,"Done")
A25: 46275 | B25: Thu | C25: W4 | F25: N/A | J25: =COUNTIF(D25:I25,"Done")
A26: 46276 | B26: Fri | C26: W4 | F26: N/A | J26: =COUNTIF(D26:I26,"Done")
A27: 46279 | B27: Mon | C27: W5 | F27: N/A | J27: =COUNTIF(D27:I27,"Done")
A28: 46280 | B28: Tue | C28: W5 | F28: N/A | J28: =COUNTIF(D28:I28,"Done")
A29: 46281 | B29: Wed | C29: W5 | J29: =COUNTIF(D29:I29,"Done")
A30: 46282 | B30: Thu | C30: W5 | F30: N/A | J30: =COUNTIF(D30:I30,"Done")
A31: 46283 | B31: Fri | C31: W5 | F31: N/A | J31: =COUNTIF(D31:I31,"Done")
A32: 46286 | B32: Mon | C32: W6 | F32: N/A | J32: =COUNTIF(D32:I32,"Done")
A33: 46287 | B33: Tue | C33: W6 | F33: N/A | J33: =COUNTIF(D33:I33,"Done")
A34: 46288 | B34: Wed | C34: W6 | J34: =COUNTIF(D34:I34,"Done")
A35: 46289 | B35: Thu | C35: W6 | F35: N/A | J35: =COUNTIF(D35:I35,"Done")
A36: 46290 | B36: Fri | C36: W6 | F36: N/A | J36: =COUNTIF(D36:I36,"Done")
A37: 46293 | B37: Mon | C37: W7 | F37: N/A | J37: =COUNTIF(D37:I37,"Done")
A38: 46294 | B38: Tue | C38: W7 | F38: N/A | J38: =COUNTIF(D38:I38,"Done")
A39: 46295 | B39: Wed | C39: W7 | J39: =COUNTIF(D39:I39,"Done")
A40: OCTOBER 2026
...

Sheet 90-Day Overview
A1: The first 90 days
A2: 17 August to 15 November 2026. Week 13 closes day 90. Counts pull live from the Tasks tab this is where you look at progress, that is where you change it.
A4: THE THREE CHECKPOINTS — what has to be true, and by when
A5: Checkpoint | B5: Date | C5: What must be true by then | G5: On track | H5: Notes
A6: Day 30 | B6: 46280 | C6: Google profile claimed, verified, complete and posting daily. All 17 existing listings corrected AND verified at L6M 4L9. Design signed off, build two weeks in. Review asks going out every day.
A7: Day 60 | B7: 46310 | C7: Site live. Every treatment page published, Search Console verified, sitemap submitted. Every citation repointed at the live URL. Ads running on three audiences.
A8: Day 90 | B8: 46341 | C8: Eight to ten new reviews. Visible in the map pack for 'botox oakville' (480 searches a month) and 'lip filler oakville'. First two or three articles live and indexed. Local link building started. Note: 'nurse injector oakville' has no measurable search volume - own it, but do not measure by it.
A10: WEEK BY WEEK — the first 90 days
A11: Week | B11: Dates | C11: Phase | D11: The one thing that matters | E11: Tasks due | F11: Done | G11: Progress | H11: Status | I11: Notes
A12: W1 | B12: 17 Aug – 23 Aug | C12: Foundation | D12: Claim and verify the Google profile. Nothing else can start until it is settled | E12: =COUNTIF(Tasks!$C:$C,"W1") | F12: =COUNTIFS(Tasks!$C:$C,"W1",Tasks!$J:$J,"Done") | G12: =IFERROR(F12/E12,0) | H12: Done
A13: W2 | B13: 24 Aug – 30 Aug | C13: Foundation | D13: Design sign-off Friday 28 August, and the citation corrections begin | E13: =COUNTIF(Tasks!$C:$C,"W2") | F13: =COUNTIFS(Tasks!$C:$C,"W2",Tasks!$J:$J,"Done") | G13: =IFERROR(F13/E13,0) | H13: Not started
A14: W3 | B14: 31 Aug – 06 Sep | C14: Build | D14: Design signed off Monday. BUILD STARTS 1 SEPTEMBER | E14: =COUNTIF(Tasks!$C:$C,"W3") | F14: =COUNTIFS(Tasks!$C:$C,"W3",Tasks!$J:$J,"Done") | G14: =IFERROR(F14/E14,0) | H14: Not started
A15: W4 | B15: 07 Sep – 13 Sep | C15: Build | D15: Home and contact complete in staging. Citations verified, not just corrected | E15: =COUNTIF(Tasks!$C:$C,"W4") | F15: =COUNTIFS(Tasks!$C:$C,"W4",Tasks!$J:$J,"Done") | G15: =IFERROR(F15/E15,0) | H15: Not started
A16: W5 | B16: 14 Sep – 20 Sep | C16: Build | D16: First four treatment pages. The review ask is now a daily habit | E16: =COUNTIF(Tasks!$C:$C,"W5") | F16: =COUNTIFS(Tasks!$C:$C,"W5",Tasks!$J:$J,"Done") | G16: =IFERROR(F16/E16,0) | H16: Not started
A17: W6 | B17: 21 Sep – 27 Sep | C17: Build | D17: Second pair of treatment pages. Ad audiences built | E17: =COUNTIF(Tasks!$C:$C,"W6") | F17: =COUNTIFS(Tasks!$C:$C,"W6",Tasks!$J:$J,"Done") | G17: =IFERROR(F17/E17,0) | H17: Not started
A18: W7 | B18: 28 Sep – 04 Oct | C18: Build | D18: Last treatment pages and the area page. Mobile speed pass | E18: =COUNTIF(Tasks!$C:$C,"W7") | F18: =COUNTIFS(Tasks!$C:$C,"W7",Tasks!$J:$J,"Done") | G18: =IFERROR(F18/E18,0) | H18: Not started
A19: W8 | B19: 05 Oct – 11 Oct | C19: Launch | D19: LAUNCH WEEK. Search Console verified, sitemap in, every listing repointed | E19: =COUNTIF(Tasks!$C:$C,"W8") | F19: =COUNTIFS(Tasks!$C:$C,"W8",Tasks!$J:$J,"Done") | G19: =IFERROR(F19/E19,0) | H19: Not started
A20: W9 | B20: 12 Oct – 18 Oct | C20: Index and optimise | D20: Confirm every page is indexed. First local link submissions | E20: =COUNTIF(Tasks!$C:$C,"W9") | F20: =COUNTIFS(Tasks!$C:$C,"W9",Tasks!$J:$J,"Done") | G20: =IFERROR(F20/E20,0) | H20: Not started
A21: W10 | B21: 19 Oct – 25 Oct | C21: Index and optimise | D21: On-page pass on the four highest-intent pages. First article | E21: =COUNTIF(Tasks!$C:$C,"W10") | F21: =COUNTIFS(Tasks!$C:$C,"W10",Tasks!$J:$J,"Done") | G21: =IFERROR(F21/E21,0) | H21: Not started
A22: W11 | B22: 26 Oct – 01 Nov | C22: Index and optimise | D22: Fix whatever Search Console flags. Second article | E22: =COUNTIF(Tasks!$C:$C,"W11") | F22: =COUNTIFS(Tasks!$C:$C,"W11",Tasks!$J:$J,"Done") | G22: =IFERROR(F22/E22,0) | H22: Not started
A23: W12 | B23: 02 Nov – 08 Nov | C23: Index and optimise | D23: Month three review and a rank check against the baseline | E23: =COUNTIF(Tasks!$C:$C,"W12") | F23: =COUNTIFS(Tasks!$C:$C,"W12",Tasks!$J:$J,"Done") | G23: =IFERROR(F23/E23,0) | H23: Not started
A24: W13 | B24: 09 Nov – 15 Nov | C24: Review | D24: DAY 90. Full read against the week-one baseline | E24: =COUNTIF(Tasks!$C:$C,"W13") | F24: =COUNTIFS(Tasks!$C:$C,"W13",Tasks!$J:$J,"Done") | G24: =IFERROR(F24/E24,0) | H24: Not started
A26: AFTER DAY 90 — the second half
A27: Month | B27: Dates | C27: Theme
A28: Month 4 | B28: 9 Nov – 6 Dec | C28: Depth on the pages that earn. Thin pages expanded, gallery, articles four to six
A29: Month 5 | B29: 7 Dec – 10 Jan | C29: Hold the cadence through the holidays. Reduced posting, never stopped posting
A30: Month 6 | B30: 11 Jan – 14 Feb | C30: Compound it. Near-miss queries, technical audit, the six-month report
A31: Week 13 is both the day-90 review and the first week of month four. It appears in two places on purpose.
A33: THE DATES THAT DO NOT MOVE
A34: Date | B34: What | C34: Why it matters | G34: Status | H34: Notes
A35: 46265 | B35: Design sign-off | C35: The build gate. Everything after it moves one-for-one | G35: Not started
A36: 46266 | B36: Build starts | C36: Hosting, DNS, platform, page scaffolding | G36: Not started
A37: 46300 | B37: Launch week begins | C37: Site live by Sunday 11 October | G37: Not started
A38: 46341 | B38: Day 90 review | C38: Every number against the week-one baseline | G38: Not started

Sheet Tasks
A1: ID | B1: Month | C1: Week | D1: Due | E1: Area | F1: Task | G1: Owner | H1: Cadence | I1: Priority | J1: Status | K1: Date done | L1: Notes / blockers
A2: 3 | B2: Month 1 | C2: W1 | D2: 46257 | E2: Google profile | F2: Claim and verify the Google Business Profile | G2: Agency | H2: One-off | I2: High | J2: Done
A3: 5 | B3: Month 1 | C3: W1 | D3: 46257 | E3: Google profile | F3: Set real opening hours on GBP for every day of the week | G3: Agency | H3: One-off | I3: High | J3: Done
A4: 6 | B4: Month 1 | C4: W1 | D4: 46257 | E4: Google profile | F4: Choose the primary GBP category | G4: Agency | H4: One-off | I4: High | J4: Done
A5: 7 | B5: Month 1 | C5: W1 | D5: 46257 | E5: Google profile | F5: Choose secondary categories that avoid colliding with Allure's listing | G5: Agency | H5: One-off | I5: High | J5: Done
A6: 8 | B6: Month 1 | C6: W1 | D6: 46257 | E6: Google profile | F6: Replace the dead website link on GBP with the booking link until the site is live | G6: Agency | H6: One-off | I6: High | J6: Done
A7: 9 | B7: Month 1 | C7: W1 | D7: 46257 | E7: Google profile | F7: Upload real photos to GBP: treatment room, you, the space | G7: Both | H7: One-off | I7: High | J7: In progress
A8: 10 | B8: Month 1 | C8: W1 | D8: 46257 | E8: Citations | F8: Decide on one email address and one phone number to use everywhere | G8: Cleo | H8: One-off | I8: High | J8: In progress
A9: 11 | B9: Month 1 | C9: W1 | D9: 46257 | E9: Citations | F9: Audit every listing that mentions the practice and record the wrong NAP on the Citations tab | G9: Agency | H9: One-off | I9: High | J9: Not started
A10: 12 | B10: Month 1 | C10: W1 | D10: 46257 | E10: Citations | F10: Fill in THE RECORD on the Local Citations tab: one name, one address, one phone, one email | G10: Both | H10: One-off | I10: High | J10: Not started
A11: 13 | B11: Month 1 | C11: W1 | D11: 46257 | E11: Daily routine | F11: Start the daily routine: GBP post, Instagram, on-page, review ask, citation | G11: Cleo | H11: Daily | I11: High | J11: Done
A12: 14 | B12: Month 1 | C12: W1 | D12: 46257 | E12: Daily routine | F12: Agree who does which daily slot and put it in the calendar | G12: Both | H12: One-off | I12: High | J12: Done
A13: 15 | B13: Month 1 | C13: W1 | D13: 46257 | E13: Measurement | F13: Record the baseline: 12 reviews, 5.0 average, GBP calls, views and direction requests | G13: Agency | H13: One-off | I13: High | J13: Not started
... A148: 155 | B148: Month 6 | C148: W26 | D148: 46432 | E148: Website | F148: Hand over the site documentation and every login | G148: Agency | H148: One-off | I148: High | J148: Not started
A149: 156 | B149: Month 1 | C149: W1 | D149: 46257 | E149: Citations | F149: Verify the postal code L6M 4L9 against a Canada Post address lookup and the lease, then lock THE RECORD | G149: Cleo | H149: One-off | I149: High | J149: Not started | L149: This reverses the correction instruction on 17 listings. Confirm once, in writing, before anything is submitted
A150: 157 | B150: Month 2 | C150: W6 | D150: 46285 | E150: Website | F150: Decide whether to add laser hair removal as a service - 480 searches a month at KD 9, and it is not offered today | G150: Cleo | H150: One-off | I150: Medium | J150: Not started | L150: The single biggest untapped term in the Target Keywords tab. A service decision, not an SEO one
A151: 158 | B151: Month 2 | C151: W3 | D151: 46271 | E151: Website | F151: Sign off the keyword-to-page map on the Site Structure tab before the build starts | G151: Both | H151: One-off | I151: High | J151: Not started | L151: One page per keyword. Merging lip filler and dermal filler would cannibalise both
A152: 159 | B152: Month 2 | C152: W7 | D152: 46292 | E152: Measurement | F152: Create the Semrush project for luxurybeautybycleo.ca | G152: Agency | H152: One-off | I152: High | J152: Not started | L152: No Semrush project exists today. Position Tracking and Site Audit both require one before either can run
A153: 160 | B153: Month 2 | C153: W7 | D153: 46292 | E153: Measurement | F153: Configure Semrush Position Tracking: keywords from the Target Keywords tab, geo-targeted to Oakville ON, mobile and desktop | G153: Agency | H153: One-off | I153: High | J153: Not started | L153: Track Tier 1 and Tier 2 only. Tier 4 has no measurable volume and would just add noise
A154: 161 | B154: Month 2 | C154: W7 | D154: 46292 | E154: Website | F154: Install the Microsoft Clarity tag sitewide and verify it is recording, before launch | G154: Agency | H154: One-off | I154: High | J154: Not started | L154: Must be live on launch day or the first weeks of visitor behaviour are lost and cannot be recovered
A155: 162 | B155: Month 3 | C155: W8 | D155: 46299 | E155: Website | F155: Link Microsoft Clarity to Google Analytics and set the booking-link click as a tracked event | G155: Agency | H155: One-off | I155: High | J155: Not started | L155: Without the event, heatmaps show where people click but not whether they booked
A156: 163 | B156: Month 3 | C156: W9 | D156: 46306 | E156: Measurement | F156: Enable Semrush Site Audit, run the first crawl at launch and record the health score as the baseline | G156: Agency | H156: One-off | I156: High | J156: Not started | L156: Needs a resolving site - cannot run before launch
A157: 164 | B157: Month 3 | C157: W9 | D157: 46306 | E157: Measurement | F157: Log Semrush visibility and position changes to the Metrics tab | G157: Agency | H157: Weekly | I157: Medium | J157: Not started | L157: Slots into the existing Monday insights block on the Daily Routine tab
A158: 165 | B158: Month 3 | C158: W9 | D158: 46306 | E158: Measurement | F158: Review Clarity heatmaps and session recordings for the week, and log what you found on the Heatmap Tracking tab | G158: Agency | H158: Weekly | I158: Medium | J158: Not started | L158: Weekly for the first month after launch, then monthly. A finding with no logged change is not a finding
A159: 166 | B159: Month 3 | C159: W10 | D159: 46313 | E159: Measurement | F159: Log the Site Audit health score and new issue count to the Metrics tab | G159: Agency | H159: Monthly | I159: Medium | J159: Not started
A160: 167 | B160: Month 3 | C160: W10 | D160: 46313 | E160: Content | F160: Confirm the blog pillar order on the Blog Pillars tab - Cost & Value ships first | G160: Both | H160: One-off | I160: Medium | J160: Not started | L160: Lowest difficulty and highest commercial intent of the four pillars

Sheet Site Build
A1: Website build timeline
A2: Approved, full build. Real dates, not weeks-from-approval. Everything after 31 August slips one-for-one if the design sign-off slips.
A4: When | B4: What we do | C4: What we need from Cleo | D4: Status | E4: Date done | F4: Notes
A5: Aug 24 - 28 | B5: Planning and design: sitemap, page inventory, wireframes for home, contact and the treatment template, keyword-to-page map, brand kit pulled from design/brand | C5: Registrar login, treatment list with current pricing, photos of the room, a headshot, logo files | D5: Not started
A6: Aug 31 | B6: Design sign-off. This is the gate — nothing is built before it clears | C6: Sign off the wireframes and the look, in writing | D6: Not started
A7: Sep 1 - 6 | B7: BUILD STARTS. Hosting sorted, DNS pointed at the new site, platform set up, page structure scaffolded | C7: Nothing. This week is ours | D7: Not started
A8: Sep 7 - 13 | B8: Home and contact complete in staging: corrected address at L6M 4L9, real hours, booking link, LocalBusiness and Service schema, title tags and meta descriptions | C8: Read the home page copy and approve it | D8: Not started
A9: Sep 14 - 27 | B9: Treatment pages: lip filler, dermal filler and facial balancing, anti-wrinkle injections, skin boosters. Internal linking, image compression, alt text | C9: Read the copy and confirm every claim is one you can stand behind | D9: Not started
A10: Sep 28 - Oct 4 | B10: Remaining treatment pages: dermaplaning, electrolysis, Belkyra. The Oakville and surrounding-area page. Mobile speed pass | C10: Nothing. This week is ours | D10: Not started
A11: Oct 5 - 11 | B11: LAUNCH. Search Console verified, sitemap submitted, analytics running, GBP website field repointed, every citation updated to the new URL | C11: Final sign-off before it goes live | D11: Not started
A12: Oct 12 - Nov 8 | B12: Indexing and on-page. Fix whatever Search Console flags, FAQ schema on the treatment pages, the first three question-intent articles | C12: The questions you get asked most in consults | D12: Not started
A13: Nov 9 - Feb 14 | B13: Depth. Weight-loss page, before-and-after gallery, five more articles, near-miss query optimisation, technical audit, handover | C13: Consent-cleared photos as they come, and the consult questions | D13: Not started

Sheet Target Keywords
A1: Target keywords
A2: All volume, difficulty and CPC figures below are live Semrush data, Canada database, pulled 21 August 2026. Nothing here is estimated. Re-pull each quarter.
A4: HOW TO READ THIS
A5: Volume is monthly Canadian searches. KD is Semrush keyword difficulty, 0 to 100 - under 15 is reachable for a new site, over 40 needs authority you will not have this year.
A6: Tier 1 is what the treatment pages are built to win. Tier 2 is adjacent and area terms. Tier 3 feeds the blog. Tier 4 is worth owning but will never show up in a traffic report.
A7: One keyword, one page. Two pages chasing the same term split the signal and neither ranks.
A9: TIER 1 - MONEY TERMS. These are what the treatment pages are built to win.
A10: Nine of the eleven sit at KD 25 or below. This is a soft local SERP - Reddit outranks most clinics for botox oakville.
A11: Keyword | B11: Volume /mo | C11: KD | D11: CPC (CAD) | E11: Intent | F11: Target page | G11: Channel | H11: Current rank | I11: Last checked | J11: Notes
A12: botox oakville | B12: 480 | C12: 25 | D12: 0 | E12: Commercial | F12: /anti-wrinkle-injections/ | G12: Map pack + organic | J12: The biggest local prize. Reddit ranks #2 for this today and oakvillederm #1 - the SERP is soft.
A13: lip filler oakville | B13: 170 | C13: 7 | D13: 2.45 | E13: Commercial | F13: /lip-filler/ | G13: Organic | J13: KD 7. The roadmap called this 'competitive, first page not guaranteed'. The data says otherwise - take it.
A14: med spa oakville | B14: 140 | C14: 29 | D14: 1.35 | E14: Commercial | F14: / | G14: Map pack + organic | J14: Hardest of the tier. Home page term, won on reviews and profile strength as much as copy.
A15: electrolysis oakville | B15: 140 | C15: 11 | D15: 0.81 | E15: Commercial | F15: /electrolysis/ | G15: Organic | J15: Confirmed low competition, as the roadmap assumed. Real volume behind it.
A16: lip injections oakville | B16: 110 | C16: 5 | D16: 2.03 | E16: Transactional | F16: /lip-filler/ | G16: Organic | J16: Transactional intent. Secondary H2 on the lip filler page - NOT its own page, it would cannibalise.
A17: dermal filler oakville | B17: 90 | C17: 5 | D17: 4.8 | E17: Commercial | F17: /dermal-filler-facial-balancing/ | G17: Organic | J17: Lowest difficulty with real volume, and the highest CPC in the local set - the most commercially valuable term here.
A18: best botox oakville | B18: 70 | C18: 16 | D18: 1.84 | E18: Commercial | F18: /anti-wrinkle-injections/ | G18: Organic | J18: Review-driven. Will not move until the review count climbs; revisit month 3.
A19: botox oakville ontario | B19: 50 | C19: 0 | D19: 0 | E19: Commercial | F19: /anti-wrinkle-injections/ | G19: Organic | J19: KD 0. Free win - one H2 and a mention in the meta description.
A20: dermaplaning oakville | B20: 40 | C20: 0 | D20: 1.16 | E20: Commercial | F20: /dermaplaning/ | G20: Organic | J20: KD 0. Should rank within weeks of launch.
A21: medspa oakville | B21: 30 | C21: 0 | D21: 1.36 | E21: Commercial | F21: / | G21: Organic | J21: Spelling variant of med spa oakville. Same page, no separate treatment.
A22: belkyra oakville | B22: 10 | C22: 0 | D22: 0 | E22: Commercial | F22: /belkyra/ | G22: Organic | J22: Tiny, but uncontested. Worth a page because nobody else has one.
A24: TIER 2 - ADJACENT SERVICES AND SURROUNDING AREA
A25: Near-me terms are won by the Google profile, never by a page. Burlington and Mississauga wait until Oakville is won.
A26: Keyword | B26: Volume /mo | C26: KD | D26: CPC (CAD) | E26: Intent | F26: Target page | G26: Channel | H26: Current rank | I26: Last checked | J26: Notes
A27: laser hair removal oakville | B27: 480 | C27: 9 | D27: 1.76 | E27: Commercial | F27: -- not a service today -- | G27: Decision needed | J27: THE BIGGEST UNTAPPED TERM IN THIS SHEET. 480/mo at KD 9 and Cleo does not offer it. Decide whether to add the service.
A28: facial oakville | B28: 320 | C28: 9 | D28: 1.13 | E28: Commercial | F28: /dermaplaning/ | G28: Organic | J28: Dermaplaning is a facial. Worth an H2 and an internal link - 8x the volume of dermaplaning oakville.
A29: skin clinic oakville | B29: 140 | C29: 32 | D29: 1.26 | E29: Commercial | F29: / | G29: Organic | J29: Home page secondary term.
A30: weight loss clinic oakville | B30: 70 | C30: 38 | D30: 4.81 | E30: Commercial | F30: /weight-loss/ | G30: Organic | J30: Highest CPC in the whole set at $4.81, and the hardest KD. Month 4 pre-launch page, month 6 full page.
A31: nurse injector toronto | B31: 50 | C31: 0 | D31: 0 | E31: Commercial | F31: /about-np-cleo/ | G31: Organic | J31: KD 0. 'nurse injector' has volume in Toronto but none in Oakville - see Tier 4.
A32: aesthetic clinic oakville | B32: 40 | C32: 0 | D32: 0 | E32: Commercial | F32: / | G32: Organic | J32: KD 0.
A33: nurse injector near me | B33: 30 | C33: 0 | D33: 1.68 | E33: Commercial | F33: GBP | G33: Map pack only | J33: Won by the Google profile, not the site.
A34: cosmetic clinic oakville | B34: 30 | C34: 0 | D34: 1.39 | E34: Commercial | F34: / | G34: Organic | J34: KD 0.
A35: filler oakville | B35: 20 | C35: 0 | D35: 0 | E35: Commercial | F35: /dermal-filler-facial-balancing/ | G35: Organic | J35: Head-term variant.
A36: injectables oakville | B36: 10 | C36: 0 | D36: 0 | E36: Commercial | F36: / | G36: Organic | J36: Small, but KD 0.
A37: botox near me | B37: 6600 | C37: 24 | D37: 2.25 | E37: Commercial | F37: GBP | G37: Map pack only | J37: Huge, but national and won only by the Google profile. Never a page target.
A38: med spa near me | B38: 880 | C38: 24 | D38: 1.45 | E38: Commercial | F38: GBP | G38: Map pack only | J38: Depends entirely on resolving the Allure same-address filtering.
... A41: lip filler burlington | B41: 90 | C41: 9 | D41: 2.04 | E41: Commercial | F41: /oakville-and-area/ | G41: Month 5+ | J41: KD 9 - the easiest of the Burlington set.
A42: med spa burlington | B42: 70 | C42: 28 | D42: 1.68 | E42: Commercial | F42: /oakville-and-area/ | G42: Month 5+
A43: botox mississauga | B43: 480 | C43: 17 | D43: 0 | E43: Commercial | F43: -- watch only -- | G43: Watch | J43: Skin Vitality territory (10,350 keywords, 33,870 visits/mo). Outside the 15km service area. Do not chase.
A44: lip filler mississauga | B44: 260 | C44: 18 | D44: 1.76 | E44: Commercial | F44: -- watch only -- | G44: Watch | J44: Outside service area. Watch only.
A46: TIER 3 - QUESTION TERMS. These feed the blog, not the treatment pages.
...

Sheet Site Structure
A1: Site structure
A2: The keyword-to-page map the Site Build tab calls for in the Aug 24 - 28 planning week. Sign this off before the build starts on 1 September. Volumes are Semrush CA, 21 Aug 2026.
A4: THE RULES THIS MAP FOLLOWS
A5: One keyword, one page. lip filler oakville and dermal filler oakville are separate pages - merging them splits the signal and neither ranks.
A6: Title tags are 60 characters or fewer, meta descriptions 155 or fewer, so Google shows them whole.
A7: Every treatment page links to contact and to at least one article. Every article links back to its treatment page. That internal linking is what makes the blog worth writing.
A8: Depth 0 is the home page, 1 is one click from it, 2 is two. Nothing a patient needs should sit deeper than 2.
A10: CORE PAGES
A11: URL path | B11: Page type | C11: Depth | D11: Primary keyword | E11: Vol /mo | F11: KD | G11: Secondary keywords | H11: Title tag (max 60) | I11: Meta description (max 155) | J11: H1 | K11: Schema | L11: Linked from | M11: Links to | N11: Build week | O11: Status
A12: / | B12: Home | C12: 0 | D12: med spa oakville | E12: 140 | F12: 29 | G12: medspa oakville; skin clinic oakville; aesthetic clinic oakville; cosmetic clinic oakville; injectables oakville | H12: Med Spa in Oakville | Luxury Beauty by Cleo R. | I12: Nurse-practitioner-led injectables and skin treatments in Oakville. Lip filler, dermal filler, skin boosters and dermaplaning. Book with Cleo. | J12: Injectables and skin treatments in Oakville | K12: MedicalBusiness + LocalBusiness | L12: - | M12: Every treatment page, contact, about | N12: Sep 7 - 13 | O12: Not started
A13: /contact/ | B13: Contact | C13: 1 | D13: med spa oakville | E13: 140 | F13: 29 | G13: directions; hours; booking | H13: Contact | Luxury Beauty by Cleo R. Oakville | I13: 3060 Preserve Drive, Oakville ON L6M 4L9. Opening hours, directions and booking for Luxury Beauty by Cleo R. | J13: Find us in Oakville | K13: LocalBusiness | L13: Home, every treatment page | M13: Booking link | N13: Sep 7 - 13 | O13: Not started
A14: /about-np-cleo/ | B14: About | C14: 1 | D14: nurse injector oakville | E14: no data | F14: - | G14: nurse injector toronto (50); nurse injector near me (30) | H14: About Cleo Rukovo, NP | Nurse Injector in Oakville | I14: Cleo Rukovo is a nurse practitioner and injector in Oakville. Training, approach and what a first appointment looks like. | J14: Meet Cleo Rukovo, NP | K14: Person + MedicalBusiness | L14: Home, every treatment page | M14: Contact, treatment pages | N14: Sep 7 - 13 | O14: Not started
A15: /lip-filler/ | B15: Treatment | C15: 1 | D15: lip filler oakville | E15: 170 | F15: 7 | G15: lip injections oakville (110, KD 5); filler oakville (20) | H15: Lip Filler in Oakville | Luxury Beauty by Cleo R. | I15: Lip filler in Oakville with nurse practitioner Cleo Rukovo. What it involves, how long it lasts, and what it costs. | J15: Lip filler in Oakville | K15: Service + FAQPage | L15: Home, /results/, blog articles | M15: Contact, /results/, /blog/how-long-does-lip-filler-last/ | N15: Sep 14 - 27 | O15: Not started
A16: /dermal-filler-facial-balancing/ | B16: Treatment | C16: 1 | D16: dermal filler oakville | E16: 90 | F16: 5 | G16: cheek filler oakville; facial balancing oakville; filler oakville (20) | H16: Dermal Filler & Facial Balancing | Oakville | I16: Dermal filler and facial balancing in Oakville. A nurse practitioner's approach to proportion rather than volume. | J16: Dermal filler and facial balancing | K16: Service + FAQPage | L16: Home, /lip-filler/ | M16: Contact, /results/ | N16: Sep 14 - 27 | O16: Not started
A17: /anti-wrinkle-injections/ | B17: Treatment | C17: 1 | D17: botox oakville | E17: 480 | F17: 25 | G17: best botox oakville (70, KD 16); botox oakville ontario (50, KD 0) | H17: Anti-Wrinkle Injections in Oakville | Cleo R. | I17: Anti-wrinkle injections in Oakville with a nurse practitioner. How treatment works, what to expect, and how long results last. | J17: Anti-wrinkle injections in Oakville | K17: Service + FAQPage | L17: Home, blog articles | M17: Contact, /blog/baby-botox-and-preventative-treatment/ | N17: Sep 14 - 27 | O17: Not started
A18: /skin-boosters/ | B18: Treatment | C18: 1 | D18: skin booster oakville | E18: no data | F18: - | G18: what are skin boosters (90, national); what is a skin booster (90) | H18: Skin Boosters in Oakville | Luxury Beauty by Cleo R. | I18: Skin boosters in Oakville. What they are, who they suit, and how they differ from filler. With nurse practitioner Cleo Rukovo. | J18: Skin boosters in Oakville | K18: Service + FAQPage | L18: Home, /blog/what-are-skin-boosters/ | M18: Contact | N18: Sep 14 - 27 | O18: Not started
A19: /dermaplaning/ | B19: Treatment | C19: 1 | D19: dermaplaning oakville | E19: 40 | F19: 0 | G19: facial oakville (320, KD 9) - 8x the volume, same page | H19: Dermaplaning in Oakville | Luxury Beauty by Cleo R. | I19: Dermaplaning in Oakville. A gentle resurfacing facial that removes dead skin and fine hair. Book with Cleo Rukovo, NP. | J19: Dermaplaning in Oakville | K19: Service + FAQPage | L19: Home, /blog/what-is-dermaplaning/ | M19: Contact | N19: Sep 28 - Oct 4 | O19: Not started
A20: /electrolysis/ | B20: Treatment | C20: 1 | D20: electrolysis oakville | E20: 140 | F20: 11 | G20: electrolysis vs laser hair removal (480, KD 28) | H20: Electrolysis in Oakville | Luxury Beauty by Cleo R. | I20: Permanent hair removal by electrolysis in Oakville. How it compares to laser, what a session involves, and how many you need. | J20: Electrolysis in Oakville | K20: Service + FAQPage | L20: Home, /blog/electrolysis-vs-laser-hair-removal/ | M20: Contact | N20: Sep 28 - Oct 4 | O20: Not started
A21: /belkyra/ | B21: Treatment | C21: 1 | D21: belkyra oakville | E21: 10 | F21: 0 | G21: - | H21: Belkyra in Oakville | Luxury Beauty by Cleo R. | I21: Belkyra treatment in Oakville for fullness under the chin. What it involves and how many sessions are typical. | J21: Belkyra in Oakville | K21: Service + FAQPage | L21: Home | M21: Contact | N21: Sep 28 - Oct 4 | O21: Not started
A22: /oakville-and-area/ | B22: Area | C22: 1 | D22: botox burlington | E22: 390 | F22: 37 | G22: lip filler burlington (90, KD 9); med spa burlington (70, KD 28); botox glen abbey | H22: Serving Oakville, Burlington, Milton & Mississauga | I22: Luxury Beauty by Cleo R. serves Oakville, Burlington, Milton, Mississauga, Glen Abbey, Joshua Creek and Bronte. | J22: Where we serve | K22: LocalBusiness | L22: Home, contact | M22: Contact, treatment pages | N22: Sep 28 - Oct 4 | O22: Not started
A23: /results/ | B23: Gallery | C23: 1 | D23: lip filler before and after | E23: 1300 | F23: - | G23: botox before and after (1900). Difficulty for both not pulled - Semrush API units exhausted | H23: Before & After | Luxury Beauty by Cleo R. Oakville | I23: Real before-and-after results from Luxury Beauty by Cleo R. in Oakville. Every photo published with written consent. | J23: Before and after | K23: ImageGallery | L23: Home, every treatment page | M23: Treatment pages, contact | N23: Nov 9 - Feb 14 | O23: Not started
A24: /weight-loss/ | B24: Treatment | C24: 1 | D24: weight loss clinic oakville | E24: 70 | F24: 38 | G24: - | H24: Weight Loss Support in Oakville | Cleo Rukovo, NP | I24: Nurse-practitioner-led weight loss support in Oakville. What the programme involves and who it suits. | J24: Weight loss support in Oakville | K24: Service + FAQPage | L24: Home | M24: Contact | N24: Month 4 pre-launch, month 6 full | O24: Not started
A25: /blog/ | B25: Index | C25: 1 | D25: - | E25: no data | F25: - | G25: - | H25: Blog | Luxury Beauty by Cleo R. Oakville | I25: Straight answers to the questions asked most in the treatment room, from a nurse practitioner in Oakville. | J25: Questions we get asked | K25: Blog | L25: Home, footer | M25: Every article | N25: Oct 12 - Nov 8 | O25: Not started
A27: ARTICLES - eight scheduled, three in the backlog. See the Blog Pillars tab for why each exists.
A28: URL path | B28: Page type | C28: Depth | D28: Primary keyword | E28: Vol /mo | F28: KD | G28: Pillar | H28: Links to treatment page | I28: Week | J28: Due | K28: Status
A29: /blog/how-much-does-lip-filler-cost-in-oakville/ | B29: Article | C29: 2 | D29: how much is lip filler | E29: 390 | F29: 11 | G29: Cost & Value | H29: /lip-filler/ | I29: W10 | J29: Oct 12 - 18 | K29: Scheduled
A30: /blog/what-anti-wrinkle-treatment-costs-in-ontario/ | B30: Article | C30: 2 | D30: how much does botox cost in ontario | E30: 90 | F30: 4 | G30: Cost & Value | H30: /anti-wrinkle-injections/ | I30: W11 | J30: Oct 19 - 25 | K30: Scheduled
A31: /blog/how-long-does-lip-filler-last/ | B31: Article | C31: 2 | D31: how long does lip filler last | E31: 1000 | F31: 15 | G31: Longevity & Aftercare | H31: /lip-filler/ | I31: W12 | J31: Oct 26 - Nov 1 | K31: Scheduled
A32: /blog/lip-filler-aftercare/ | B32: Article | C32: 2 | D32: lip filler aftercare | E32: 320 | F32: 14 | G32: Longevity & Aftercare | H32: /lip-filler/ | I32: W13 | J32: Nov 2 - 8 | K32: Scheduled
A33: /blog/what-is-dermaplaning/ | B33: Article | C33: 2 | D33: what is dermaplaning | E33: 880 | F33: 23 | G33: Treatment Explainers | H33: /dermaplaning/ | I33: W14 | J33: Nov 9 - 15 | K33: Scheduled
A34: /blog/what-to-expect-first-filler-appointment/ | B34: Article | C34: 2 | D34: does lip filler hurt | E34: 110 | F34: 7 | G34: First-timer, Safety & Candidacy | H34: /lip-filler/ | I34: W16 | J34: Nov 23 - 29 | K34: Scheduled
A35: /blog/electrolysis-vs-laser-hair-removal/ | B35: Article | C35: 2 | D35: electrolysis vs laser hair removal | E35: 480 | F35: 28 | G35: Treatment Explainers | H35: /electrolysis/ | I35: W18 | J35: Dec 7 - 13 | K35: Scheduled
A36: /blog/baby-botox-and-preventative-treatment/ | B36: Article | C36: 2 | D36: baby botox | E36: 480 | F36: 17 | G36: First-timer, Safety & Candidacy | H36: /anti-wrinkle-injections/ | I36: W22 | J36: Jan 4 - 10 | K36: Scheduled
A37: /blog/aftercare-anti-wrinkle-injections/ | B37: Article | C37: 2 | D37: botox aftercare | E37: 1000 | F37: 32 | G37: Longevity & Aftercare | H37: /anti-wrinkle-injections/ | I37: - | J37: Backlog | K37: Backlog
A38: /blog/what-are-skin-boosters/ | B38: Article | C38: 2 | D38: what are skin boosters | E38: 90 | F38: 23 | G38: Treatment Explainers | H38: /skin-boosters/ | I38: - | J38: Backlog | K38: Backlog
A39: /blog/who-is-not-a-candidate/ | B39: Article | C39: 2 | D39: can you get lip filler while pregnant | E39: 110 | F39: 10 | G39: First-timer, Safety & Candidacy | H39: /lip-filler/ | I39: - | J39: Backlog | K39: Backlog

Sheet Blog Pillars
A1: Blog pillars
A2: What the blog is for, which searches each pillar answers, and which of the eight scheduled articles belongs where. Volumes are Semrush CA, 21 Aug 2026.
A4: FIRST, WHAT WE FOUND
A5: There is no blog yet. Eight articles are scheduled in the tracker at weeks 10, 11, 12, 13, 14, 16, 18 and 22, but none has a topic, a keyword or a title - they are placeholder slots. This tab fills them in.
A6: The five pillars that already exist (Education, Engagement, Trust & Proof, Personality & BTS, Promo & CTA) are INSTAGRAM ENGAGEMENT PILLARS, not search pillars. They organise posts by purpose, not by what anyone types into Google. Across all 102 briefs in content/, not one targets a search term. That is not a criticism of the calendar - it is doing a different job - but it does mean the blog cannot simply inherit them.
A7: The 102 existing briefs are still the best raw material available: they are already written in Cleo's voice and already compliance-checked. The mapping below shows which Instagram pillar feeds which search pillar, so the blog is a rewrite job rather than a research job.
A9: HOW THE INSTAGRAM PILLARS MAP ONTO SEARCH
A10: Instagram pillar | B10: What it does today | C10: Feeds which blog pillar | D10: What that means in practice
A11: Education | B11: Explains a treatment or corrects a myth | C11: Treatment Explainers + First-timer, Safety & Candidacy | D11: The strongest overlap. A myth-busting carousel is an article's outline with the paragraphs removed.
A12: Engagement | B12: Polls, questions, 'this or that' | C12: None directly | D12: Engagement bait has no search demand behind it. Keep it on Instagram - but the questions people answer are free keyword research. Log the recurring ones.
A13: Trust & Proof | B13: Before-and-afters, reviews, credentials | C13: Cost & Value + the /results/ gallery | D13: Feeds the gallery page and the cost articles, where proof does the persuading.
A14: Personality & BTS | B14: Cleo on camera, the room, the day | C14: None directly | D14: No search demand, real conversion value. Belongs on the about page, not the blog.
A15: Promo & CTA | B15: Offers, availability, booking prompts | C15: Cost & Value | D15: Careful here - CNO advertising standards limit discount framing. See the compliance column.
A18: THE FOUR SEARCH PILLARS
A19: Ranked by what to write first. Cost & Value ships first: lowest difficulty, highest intent, and nobody local is answering it.
A20: Pillar | B20: Why it ranks here | C20: Anchor keywords (volume / difficulty) | D20: Total vol /mo | E20: Why this pillar exists | F20: Links to | G20: Compliance note - read before drafting
A21: 1. Cost & Value | B21: SHIP FIRST | C21: how much is lip filler (390/KD 11); how much does lip filler cost (260/KD 15); how much is lip filler in canada (110/KD 5); how much does botox cost in ontario (90/KD 4); botox cost canada (90/KD 11) | D21: 940 | E21: Lowest difficulty in the set and the highest commercial intent - somebody pricing a treatment is close to booking. Nobody local answers these honestly, which is exactly why it works. | F21: /lip-filler/, /anti-wrinkle-injections/ | G21: HIGHEST RISK. Never put a price beside a brand name and a benefit claim - that is the Health Canada line. Quote ranges for the treatment category, not the product. No 'best value', no guarantees (CNO).
A22: 2. Longevity & Aftercare | B22: Highest volume | C22: how long does lip filler last (1000/KD 15); botox aftercare (1000/KD 32); lip filler aftercare (320/KD 14); lip filler swelling (140/KD 28); what not to do after lip filler (70/KD 18); how long does lip filler swelling last (70/KD 0) | D22: 2600 | E22: The biggest pillar by volume. Reaches people who already have treatment booked or done - which is retention, review requests and word of mouth, not just traffic. | F22: /lip-filler/, /anti-wrinkle-injections/, /dermaplaning/ | G22: Aftercare instruction is clinical guidance. Keep it general and route anything specific to a consult. Never imply a guaranteed duration.
A23: 3. First-timer, Safety & Candidacy | B23: Best fit with what already exists | C23: baby botox (480/KD 17); preventative botox (210/KD 45); does lip filler hurt (110/KD 7); can you get lip filler while pregnant (110/KD 10); how to know if lip filler has gone wrong (90/KD 21) | D23: 1000 | E23: Maps almost one-to-one onto the myth-busting and candidacy carousels already written in content/. The 102 briefs in that folder are the raw material - this pillar is mostly rewriting, not researching. | F23: /lip-filler/, /anti-wrinkle-injections/, /about-np-cleo/ | G23: Candidacy and safety content is where a nurse practitioner's credential is the whole advantage. State who is NOT a candidate - it is honest, it ranks, and it filters bad bookings.
A24: 4. Treatment Explainers | B24: Widest reach, weakest intent | C24: what is dermaplaning (880/KD 23); what is a dermaplane (880/KD 24); electrolysis vs laser hair removal (480/KD 28); how to dermaplane (210/KD 27); is dermaplaning good for skin (210/KD 35); what is electrolysis hair removal (170/KD 43); what are skin boosters (90/KD 23) | D24: 2920 | E24: Feeds the two lowest-competition treatment pages, dermaplaning and electrolysis, where a page can rank with very little authority behind it. Intent is informational, so judge it on assisted bookings, not direct ones. | F24: /dermaplaning/, /electrolysis/, /skin-boosters/ | G24: Comparison content (electrolysis vs laser) must not claim superiority over another provider's service - that is a CNO advertising breach. Compare the modalities, never the clinics.
A27: THE ARTICLES, ASSIGNED
A28: Eight scheduled slots filled, plus three of the five backlog articles the Site Build tab reserves for Nov 9 - Feb 14. The last two stay open deliberately - fill them from real consult questions.
A29: Week | B29: Due | C29: Article | D29: Pillar | E29: Primary keyword | F29: Vol /mo | G29: KD | H29: Links to treatment page | I29: Status
A30: W10 | B30: Oct 12 - 18 | C30: /blog/how-much-does-lip-filler-cost-in-oakville/ | D30: Cost & Value | E30: how much is lip filler | F30: 390 | G30: 11 | H30: /lip-filler/ | I30: Scheduled
A31: W11 | B31: Oct 19 - 25 | C31: /blog/what-anti-wrinkle-treatment-costs-in-ontario/ | D31: Cost & Value | E31: how much does botox cost in ontario | F31: 90 | G31: 4 | H31: /anti-wrinkle-injections/ | I31: Scheduled
A32: W12 | B32: Oct 26 - Nov 1 | C32: /blog/how-long-does-lip-filler-last/ | D32: Longevity & Aftercare | E32: how long does lip filler last | F32: 1000 | G32: 15 | H32: /lip-filler/ | I32: Scheduled
A33: W13 | B33: Nov 2 - 8 | C33: /blog/lip-filler-aftercare/ | D33: Longevity & Aftercare | E33: lip filler aftercare | F33: 320 | G33: 14 | H33: /lip-filler/ | I33: Scheduled
A34: W14 | B34: Nov 9 - 15 | C34: /blog/what-is-dermaplaning/ | D34: Treatment Explainers | E34: what is dermaplaning | F34: 880 | G34: 23 | H34: /dermaplaning/ | I34: Scheduled
A35: W16 | B35: Nov 23 - 29 | C35: /blog/what-to-expect-first-filler-appointment/ | D35: First-timer, Safety & Candidacy | E35: does lip filler hurt | F35: 110 | G35: 7 | H35: /lip-filler/ | I35: Scheduled
A36: W18 | B36: Dec 7 - 13 | C36: /blog/electrolysis-vs-laser-hair-removal/ | D36: Treatment Explainers | E36: electrolysis vs laser hair removal | F36: 480 | G36: 28 | H36: /electrolysis/ | I36: Scheduled
A37: W22 | B37: Jan 4 - 10 | C37: /blog/baby-botox-and-preventative-treatment/ | D37: First-timer, Safety & Candidacy | E37: baby botox | F37: 480 | G37: 17 | H37: /anti-wrinkle-injections/ | I37: Scheduled
A38: - | B38: Backlog | C38: /blog/aftercare-anti-wrinkle-injections/ | D38: Longevity & Aftercare | E38: botox aftercare | F38: 1000 | G38: 32 | H38: /anti-wrinkle-injections/ | I38: Backlog
A39: - | B39: Backlog | C39: /blog/what-are-skin-boosters/ | D39: Treatment Explainers | E39: what are skin boosters | F39: 90 | G39: 23 | H39: /skin-boosters/ | I39: Backlog
A40: - | B40: Backlog | C40: /blog/who-is-not-a-candidate/ | D40: First-timer, Safety & Candidacy | E40: can you get lip filler while pregnant | F40: 110 | G40: 10 | H40: /lip-filler/ | I40: Backlog
A41: - | B41: Backlog | C41: Open slot - fill from consult questions | D41: Whichever fits | I41: Backlog
A42: - | B42: Backlog | C42: Open slot - fill from consult questions | D42: Whichever fits | I42: Backlog
A44: THE TWO COMPLIANCE RULES, IN FULL
A45: Health Canada, prescription drug advertising: a prescription product's brand name may not be paired with a benefit claim in advertising to the public. In practice - name the treatment category, describe the outcome; or name the brand and say nothing about what it does. Never both in the same breath.
A46: CNO advertising standards: no guarantees of outcome, no claims of superiority over another provider, no testimonials that imply a guaranteed result. This binds Cleo personally as a registered nurse practitioner, not just the business.

Sheet Reviews
A1: Review tracker
A2: Baseline 12 reviews at 5.0. Target 18 to 22 new ones across the six months, roughly one every ten days. Ask inside 24 hours or the number does not move. | F2: Asks sent | G2: =COUNTA(A5:A164) | H2: Reviews landed | I2: =COUNTIF(E5:E164,"Yes")
A4: Date asked | B4: Patient (initials) | C4: How we asked | D4: Asked by | E4: Review received | F4: Date received | G4: Platform | H4: Replied | I4: Notes

Sheet Citations
A1: Citations and NAP
A2: One name, one address, one phone number, everywhere. The postal code is L6M 4L9 — it is wrong on most of these today.
A4: Directory | B4: Listing URL | C4: Claimed | D4: Name correct | E4: Address and postal code correct | F4: Phone correct | G4: Website URL current | H4: Status | I4: Date done | J4: Notes
A5: Google Business Profile | B5: https://share.google/FpK3RhUmP2n3dVgUQ | C5: Yes | H5: Not started
A6: Birdeye | H6: Not started
A7: Facebook | H7: Not started
A8: Fresha | B8: https://www.fresha.com/lvp/luxury-beauty-by-cleo-r-preserve-drive-oakville-X417M2 | H8: Not started
A9: Yelp.ca | H9: Not started
A10: Yellow Pages | H10: Not started
A11: Apple Maps | H11: Not started
A12: Bing Places | H12: Not started
A13: RateMDs | H13: Not started
A14: Canadian chamber directories | H14: Not started
A15: Oakville Chamber of Commerce | H15: Not started
A16: 411.ca | H16: Not started
A17: Cylex Canada | H17: Not started
A18: Foursquare | H18: Not started
A19: Instagram profile | H19: Not started
A20: Booking system profile | H20: Not started
A21: Halton business directory | H21: Not started
A22: bookbeauty.ca | B22: https://bookbeauty.ca/listing/luxury-beauty-by-cleo-r/
A23: fresha.com

Sheet Local Citations
A1: Local citations — the build list
A2: The Citations tab fixes listings that already exist. This one builds listings where there are none. Decide the record once, then paste it, unchanged, into every form below. | F2: Submitted | G2: =COUNTIF(G37:G53,"Done") | H2: Still to do | I2: =COUNTIF(G37:G53,"Not started")
A4: THE RECORD — paste this, exactly, every time
A5: Field | B5: Value | E5: Where it gets decided
A6: Business name (exact) | B6: Luxury Beauty by Cleo R. | E6: Use this spelling everywhere. No 'Med Spa', no 'Inc', no variations
A7: Practitioner | B7: Cleo Rukovo, NP | E7: Nurse practitioner. Some healthcare directories list the person, not the practice
A8: Address line 1 | B8: 3060 Preserve Drive | E8: Confirmed
A9: Suite / unit | E9: Waiting on the Allure conversation. This is what separates you from their listing
A10: City | B10: Oakville | E10: Confirmed
A11: Province | B11: Ontario | E11: Write 'Ontario' in full, or 'ON' — pick one and never mix them
A12: Postal code | B12: L6M 4L9 | E12: Confirmed by Cleo, 21 Aug 2026. Listings showing L6M 0T9 are the error - verify against Canada Post before the mass correction
A13: Country | B13: Canada | E13: Confirmed
A14: Phone | B14: (416) 294-0452 | E14: One number, everywhere. A local 905 or 289 line beats the 416 mobile if you can get one
A15: Email | B15: Luxury.beautyaestheticz@gmail.com | E15: One address. Currently split between crukovo@ and luxury.beautyaestheticz@
A16: Website | B16: https://luxurybeautybycleo.ca | E16: Use the booking link until the site is live in October, then switch every listing
A17: Booking URL | B17: IG only | E17: Needed before any directory that offers a booking button
A18: Primary category | B18: Medical Spa | E18: Set on the Google profile first, then match it everywhere else
A19: Secondary categories | B19: Skin care clinic Weight loss service | E19: Chosen to avoid colliding with Allure's listing
A20: Short description (under 250 characters) | E20: Names the town and the treatments. No prescription drug names, no benefit claims
A21: Long description | B21: Luxury Beauty by Cleo R. is a nurse practitioner-led medical spa in Oakville, Ontario, serving clients across Burlington, Mississauga, Milton and Halton Region. Our services include lip filler, dermal filler for volume loss, anti-wrinkle injections, jawline slimming, skin boosters for hydration and glow, dermaplaning, and electrolysis. Every visit begins with a one-on-one consultation so we can plan the right approach for your features and your goals. Our philosophy is simple: the right product, the right technique, and never more than you need. Every treatment is performed by Cleo Rukovo, NP. Book your consultation today. | E21: Same rules. Write once, reuse everywhere
A22: Hours — Monday | B22: Closed | E22: All seven days. 'Closed' is an answer; blank is not
A23: Hours — Tuesday | B23: Closed
A24: Hours — Wednesday | B24: Closed
A25: Hours — Thursday | B25: Closed
A26: Hours — Friday | B26: 10:00 AM–8:00 PM
A27: Hours — Saturday | B27: Closed
A28: Hours — Sunday | B28: Closed | E28: The only hours on record anywhere today are Sunday 12 to 5
A29: Year established | B29: 2023
A30: Service area | B30: Oakville, Burlington, Milton, Mississauga, Glen Abbey, Joshua Creek, Bronte | E30: Used where a directory asks for a service radius
A31: Logo file | B31: added | E31: From design/brand
A32: Cover photo | B32: added
A33: Amber means still undecided. Every amber row above has a matching row on the Waiting On Cleo tab. Do not submit to anything below until they are all filled in — a wrong detail submitted 28 times is 28 corrections later.
A35: SUBMISSION QUEUE — one a day in the citation slot, once the record is settled
A36: Directory | B36: Type | C36: Priority | D36: Where to start | E36: Account needed | F36: Verified live | G36: Status | H36: Date submitted | I36: Live listing URL | J36: NAP checked | K36: Notes
A37: Oakville News business listing | B37: Local | C37: Medium | D37: oakvillenews.org | G37: In progress
A38: Nextdoor business page, Oakville | B38: Local | C38: Medium | D38: business.nextdoor.com | G38: Done | I38: https://ca.nextdoor.com/page/luxury-beauty-by-cleo-r-oakville-on
A39: Nurse Practitioners' Association of Ontario | B39: Healthcare | C39: High | D39: npao.org | G39: Not applicable
A40: Doctify Canada | B40: Healthcare | C40: Medium | D40: doctify.com | G40: Not applicable
A41: Booksy | B41: Healthcare | C41: Medium | D41: booksy.com | G41: In progress | K41: free trial need phone verifcation
A42: Vagaro | B42: Healthcare | C42: Medium | D42: vagaro.com | G42: In progress | K42: need payment
...

Sheet Heatmap Tracking
A1: Heatmap tracking
A2: Microsoft Clarity - free, unlimited sessions. Rankings tell you who arrived; this tells you what they did next. A page that ranks and does not book looks like a win without it.
A4: A note on Semrush: it has no heatmap product. Semrush measures the search results page and the competition; a heatmap needs a tag on your own site recording real visitors. They are different instruments and you need both.
A6: 1. SETUP - all of it before the site goes live
A7: Step | B7: Owner | C7: When | D7: Notes | E7: Status
A8: Create the Microsoft Clarity account and project for luxurybeautybycleo.ca | B8: Agency | C8: Before launch | D8: Free, no session cap, no credit card. clarity.microsoft.com | E8: Not started
A9: Install the Clarity tag sitewide, in the head of every page | B9: Agency | C9: Before launch | D9: Must be live ON launch day. Behaviour from the first weeks cannot be recovered later | E9: Not started
A10: Verify it is recording - open the site, then check the session appears | B10: Agency | C10: Before launch | E10: Not started
A11: Link Clarity to Google Analytics | B11: Agency | C11: Launch week | D11: Lets you jump from a traffic number straight to the recordings behind it | E11: Not started
A12: Set the booking-link click as a tracked event | B12: Agency | C12: Launch week | D12: Without it you see where people click, not whether they booked | E12: Not started
A13: Set up a mobile-only filter and save it | B13: Agency | C13: Launch week | D13: Most of this audience is on a phone. Desktop-weighted heatmaps will point you the wrong way | E13: Not started
